[2025-08-16 22:13:45,301] {taskinstance.py:1159} INFO - Dependencies all met for <TaskInstance: 1_load_initial_data.create_schema manual__2025-08-16T22:08:42.631357+00:00 [queued]>
[2025-08-16 22:13:45,309] {taskinstance.py:1159} INFO - Dependencies all met for <TaskInstance: 1_load_initial_data.create_schema manual__2025-08-16T22:08:42.631357+00:00 [queued]>
[2025-08-16 22:13:45,309] {taskinstance.py:1356} INFO - 
--------------------------------------------------------------------------------
[2025-08-16 22:13:45,310] {taskinstance.py:1357} INFO - Starting attempt 2 of 2
[2025-08-16 22:13:45,311] {taskinstance.py:1358} INFO - 
--------------------------------------------------------------------------------
[2025-08-16 22:13:45,319] {taskinstance.py:1377} INFO - Executing <Task(PostgresOperator): create_schema> on 2025-08-16 22:08:42.631357+00:00
[2025-08-16 22:13:45,325] {standard_task_runner.py:52} INFO - Started process 130 to run task
[2025-08-16 22:13:45,332] {standard_task_runner.py:79} INFO - Running: ['airflow', 'tasks', 'run', '1_load_initial_data', 'create_schema', 'manual__2025-08-16T22:08:42.631357+00:00', '--job-id', '5', '--raw', '--subdir', 'DAGS_FOLDER/initialise_data.py', '--cfg-path', '/tmp/tmpsewfc63q', '--error-file', '/tmp/tmpv628dtcx']
[2025-08-16 22:13:45,335] {standard_task_runner.py:80} INFO - Job 5: Subtask create_schema
[2025-08-16 22:13:45,426] {task_command.py:369} INFO - Running <TaskInstance: 1_load_initial_data.create_schema manual__2025-08-16T22:08:42.631357+00:00 [running]> on host 146f6081c4bb
[2025-08-16 22:13:45,498] {taskinstance.py:1569} INFO - Exporting the following env vars:
AIRFLOW_CTX_DAG_OWNER=airflow
AIRFLOW_CTX_DAG_ID=1_load_initial_data
AIRFLOW_CTX_TASK_ID=create_schema
AIRFLOW_CTX_EXECUTION_DATE=2025-08-16T22:08:42.631357+00:00
AIRFLOW_CTX_TRY_NUMBER=2
AIRFLOW_CTX_DAG_RUN_ID=manual__2025-08-16T22:08:42.631357+00:00
[2025-08-16 22:13:45,500] {sql.py:262} INFO - Executing: CREATE SCHEMA IF NOT EXISTS dbt_raw_data;
[2025-08-16 22:13:45,544] {taskinstance.py:1889} ERROR - Task failed with exception
Traceback (most recent call last):
  File "/usr/local/lib/python3.8/site-packages/airflow/providers/common/sql/operators/sql.py", line 263, in execute
    hook = self.get_db_hook()
  File "/usr/local/lib/python3.8/site-packages/airflow/providers/common/sql/operators/sql.py", line 181, in get_db_hook
    return self._hook
  File "/usr/local/lib/python3.8/functools.py", line 967, in __get__
    val = self.func(instance)
  File "/usr/local/lib/python3.8/site-packages/airflow/providers/common/sql/operators/sql.py", line 143, in _hook
    conn = BaseHook.get_connection(self.conn_id)
  File "/usr/local/lib/python3.8/site-packages/airflow/hooks/base.py", line 67, in get_connection
    conn = Connection.get_connection_from_secrets(conn_id)
  File "/usr/local/lib/python3.8/site-packages/airflow/models/connection.py", line 430, in get_connection_from_secrets
    raise AirflowNotFoundException(f"The conn_id `{conn_id}` isn't defined")
airflow.exceptions.AirflowNotFoundException: The conn_id `dbt_postgres_instance_raw_data` isn't defined
[2025-08-16 22:13:45,557] {taskinstance.py:1395} INFO - Marking task as FAILED. dag_id=1_load_initial_data, task_id=create_schema, execution_date=20250816T220842, start_date=20250816T221345, end_date=20250816T221345
[2025-08-16 22:13:45,567] {standard_task_runner.py:92} ERROR - Failed to execute job 5 for task create_schema (The conn_id `dbt_postgres_instance_raw_data` isn't defined; 130)
[2025-08-16 22:13:45,626] {local_task_job.py:156} INFO - Task exited with return code 1
[2025-08-16 22:13:45,672] {local_task_job.py:273} INFO - 0 downstream tasks scheduled from follow-on schedule check
