[2025-08-16 21:11:15,438] {taskinstance.py:1159} INFO - Dependencies all met for <TaskInstance: 1_load_initial_data.create_schema manual__2025-08-16T21:01:59.126025+00:00 [queued]>
[2025-08-16 21:11:15,444] {taskinstance.py:1159} INFO - Dependencies all met for <TaskInstance: 1_load_initial_data.create_schema manual__2025-08-16T21:01:59.126025+00:00 [queued]>
[2025-08-16 21:11:15,445] {taskinstance.py:1356} INFO - 
--------------------------------------------------------------------------------
[2025-08-16 21:11:15,446] {taskinstance.py:1357} INFO - Starting attempt 2 of 2
[2025-08-16 21:11:15,447] {taskinstance.py:1358} INFO - 
--------------------------------------------------------------------------------
[2025-08-16 21:11:15,454] {taskinstance.py:1377} INFO - Executing <Task(PostgresOperator): create_schema> on 2025-08-16 21:01:59.126025+00:00
[2025-08-16 21:11:15,458] {standard_task_runner.py:52} INFO - Started process 102 to run task
[2025-08-16 21:11:15,461] {standard_task_runner.py:79} INFO - Running: ['airflow', 'tasks', 'run', '1_load_initial_data', 'create_schema', 'manual__2025-08-16T21:01:59.126025+00:00', '--job-id', '352', '--raw', '--subdir', 'DAGS_FOLDER/initialise_data.py', '--cfg-path', '/tmp/tmpudg4z34z', '--error-file', '/tmp/tmpmslxtz85']
[2025-08-16 21:11:15,463] {standard_task_runner.py:80} INFO - Job 352: Subtask create_schema
[2025-08-16 21:11:15,566] {task_command.py:369} INFO - Running <TaskInstance: 1_load_initial_data.create_schema manual__2025-08-16T21:01:59.126025+00:00 [running]> on host 014eb9994ff5
[2025-08-16 21:11:15,702] {taskinstance.py:1569} INFO - Exporting the following env vars:
AIRFLOW_CTX_DAG_OWNER=airflow
AIRFLOW_CTX_DAG_ID=1_load_initial_data
AIRFLOW_CTX_TASK_ID=create_schema
AIRFLOW_CTX_EXECUTION_DATE=2025-08-16T21:01:59.126025+00:00
AIRFLOW_CTX_TRY_NUMBER=2
AIRFLOW_CTX_DAG_RUN_ID=manual__2025-08-16T21:01:59.126025+00:00
[2025-08-16 21:11:15,704] {sql.py:262} INFO - Executing: CREATE SCHEMA IF NOT EXISTS dbt_raw_data;
[2025-08-16 21:11:15,718] {crypto.py:82} WARNING - empty cryptography key - values will not be stored encrypted.
[2025-08-16 21:11:15,719] {connection.py:424} ERROR - Unable to retrieve connection from secrets backend (MetastoreBackend). Checking subsequent secrets backend.
Traceback (most recent call last):
  File "/usr/local/lib/python3.8/site-packages/airflow/models/connection.py", line 420, in get_connection_from_secrets
    conn = secrets_backend.get_connection(conn_id=conn_id)
  File "/usr/local/lib/python3.8/site-packages/airflow/utils/session.py", line 71, in wrapper
    return func(*args, session=session, **kwargs)
  File "/usr/local/lib/python3.8/site-packages/airflow/secrets/metastore.py", line 36, in get_connection
    conn = session.query(Connection).filter(Connection.conn_id == conn_id).first()
  File "/usr/local/lib/python3.8/site-packages/sqlalchemy/orm/query.py", line 2734, in first
    return self.limit(1)._iter().first()
  File "/usr/local/lib/python3.8/site-packages/sqlalchemy/engine/result.py", line 1358, in first
    return self._only_one_row(False, False, False)
  File "/usr/local/lib/python3.8/site-packages/sqlalchemy/engine/result.py", line 566, in _only_one_row
    row = onerow(hard_close=True)
  File "/usr/local/lib/python3.8/site-packages/sqlalchemy/engine/result.py", line 1240, in _fetchone_impl
    return self._real_result._fetchone_impl(hard_close=hard_close)
  File "/usr/local/lib/python3.8/site-packages/sqlalchemy/engine/result.py", line 1627, in _fetchone_impl
    row = next(self.iterator, _NO_ROW)
  File "/usr/local/lib/python3.8/site-packages/sqlalchemy/orm/loading.py", line 124, in chunks
    rows = [proc(row) for row in fetch]
  File "/usr/local/lib/python3.8/site-packages/sqlalchemy/orm/loading.py", line 124, in <listcomp>
    rows = [proc(row) for row in fetch]
  File "/usr/local/lib/python3.8/site-packages/sqlalchemy/orm/loading.py", line 955, in _instance
    state.manager.dispatch.load(state, context)
  File "/usr/local/lib/python3.8/site-packages/sqlalchemy/event/attr.py", line 320, in __call__
    fn(*args, **kw)
  File "/usr/local/lib/python3.8/site-packages/sqlalchemy/orm/mapper.py", line 3555, in _event_on_load
    instrumenting_mapper._reconstructor(state.obj())
  File "/usr/local/lib/python3.8/site-packages/airflow/models/connection.py", line 172, in on_db_load
    if self.password:
  File "/usr/local/lib/python3.8/site-packages/sqlalchemy/orm/attributes.py", line 552, in __get__
    retval = self.descriptor.__get__(instance, owner)
  File "/usr/local/lib/python3.8/site-packages/airflow/models/connection.py", line 261, in get_password
    raise AirflowException(
airflow.exceptions.AirflowException: Can't decrypt encrypted password for login=dbtuser  FERNET_KEY configuration is missing
[2025-08-16 21:11:15,758] {taskinstance.py:1889} ERROR - Task failed with exception
Traceback (most recent call last):
  File "/usr/local/lib/python3.8/site-packages/airflow/providers/common/sql/operators/sql.py", line 263, in execute
    hook = self.get_db_hook()
  File "/usr/local/lib/python3.8/site-packages/airflow/providers/common/sql/operators/sql.py", line 181, in get_db_hook
    return self._hook
  File "/usr/local/lib/python3.8/functools.py", line 967, in __get__
    val = self.func(instance)
  File "/usr/local/lib/python3.8/site-packages/airflow/providers/common/sql/operators/sql.py", line 143, in _hook
    conn = BaseHook.get_connection(self.conn_id)
  File "/usr/local/lib/python3.8/site-packages/airflow/hooks/base.py", line 67, in get_connection
    conn = Connection.get_connection_from_secrets(conn_id)
  File "/usr/local/lib/python3.8/site-packages/airflow/models/connection.py", line 430, in get_connection_from_secrets
    raise AirflowNotFoundException(f"The conn_id `{conn_id}` isn't defined")
airflow.exceptions.AirflowNotFoundException: The conn_id `dbt_postgres_instance_raw_data` isn't defined
[2025-08-16 21:11:15,770] {taskinstance.py:1395} INFO - Marking task as FAILED. dag_id=1_load_initial_data, task_id=create_schema, execution_date=20250816T210159, start_date=20250816T211115, end_date=20250816T211115
[2025-08-16 21:11:15,799] {standard_task_runner.py:92} ERROR - Failed to execute job 352 for task create_schema (The conn_id `dbt_postgres_instance_raw_data` isn't defined; 102)
[2025-08-16 21:11:15,877] {local_task_job.py:156} INFO - Task exited with return code 1
[2025-08-16 21:11:15,968] {local_task_job.py:273} INFO - 0 downstream tasks scheduled from follow-on schedule check
